{
 "cells": [
  {
   "cell_type": "markdown",
   "metadata": {},
   "source": [
    "# Importing Libraries"
   ]
  },
  {
   "cell_type": "markdown",
   "metadata": {},
   "source": [
    "The FitnessGramâ„¢ Pacer Test is a multistage aerobic capacity test that progressively gets more difficult as it continues. The 20 meter pacer test will begin in 30 seconds. Line up at the start. The running speed starts slowly, but gets faster each minute after you hear this signal. <i>beep</i> A single lap should be completed each time you hear this sound. <i>ding</i> Remember to run in a straight line, and run as long as possible. The second time you fail to complete a lap before the sound, your test is over. The test will begin on the word start. <b>On your mark, get ready, start.</b>"
   ]
  },
  {
   "cell_type": "code",
   "execution_count": null,
   "metadata": {},
   "outputs": [
    {
     "ename": "",
     "evalue": "",
     "output_type": "error",
     "traceback": [
      "\u001b[1;31mFailed to start the Kernel. \n",
      "\u001b[1;31mTraceback (most recent call last):\n",
      "\u001b[1;31m  File \"/Users/keanlee/opt/anaconda3/lib/python3.9/site-packages/traitlets/config/application.py\", line 88, in inner\n",
      "\u001b[1;31m    return method(app, *args, **kwargs)\n",
      "\u001b[1;31m  File \"/Users/keanlee/opt/anaconda3/lib/python3.9/site-packages/traitlets/config/application.py\", line 714, in parse_command_line\n",
      "\u001b[1;31m    self.update_config(self.cli_config)\n",
      "\u001b[1;31m  File \"/Users/keanlee/opt/anaconda3/lib/python3.9/site-packages/traitlets/config/configurable.py\", line 223, in update_config\n",
      "\u001b[1;31m    self._load_config(config)\n",
      "\u001b[1;31m  File \"/Users/keanlee/opt/anaconda3/lib/python3.9/site-packages/traitlets/config/configurable.py\", line 193, in _load_config\n",
      "\u001b[1;31m    warn(msg)\n",
      "\u001b[1;31m  File \"/Users/keanlee/opt/anaconda3/lib/python3.9/contextlib.py\", line 126, in __exit__\n",
      "\u001b[1;31m    next(self.gen)\n",
      "\u001b[1;31m  File \"/Users/keanlee/opt/anaconda3/lib/python3.9/site-packages/traitlets/traitlets.py\", line 1207, in hold_trait_notifications\n",
      "\u001b[1;31m    raise e\n",
      "\u001b[1;31m  File \"/Users/keanlee/opt/anaconda3/lib/python3.9/site-packages/traitlets/traitlets.py\", line 1193, in hold_trait_notifications\n",
      "\u001b[1;31m    value = trait._cross_validate(self, getattr(self, name))\n",
      "\u001b[1;31m  File \"/Users/keanlee/opt/anaconda3/lib/python3.9/site-packages/traitlets/traitlets.py\", line 620, in _cross_validate\n",
      "\u001b[1;31m    value = obj._trait_validators<a href='obj, proposal'>self.name</a>\n",
      "\u001b[1;31m  File \"/Users/keanlee/opt/anaconda3/lib/python3.9/site-packages/traitlets/traitlets.py\", line 977, in __call__\n",
      "\u001b[1;31m    return self.func(*args, **kwargs)\n",
      "\u001b[1;31m  File \"/Users/keanlee/opt/anaconda3/lib/python3.9/site-packages/notebook/notebookapp.py\", line 1522, in _notebook_dir_validate\n",
      "\u001b[1;31m    raise TraitError(trans.gettext(\"No such notebook dir: '%r'\") % value)\n",
      "\u001b[1;31mtraitlets.traitlets.TraitError: No such notebook dir: ''/kimolijones/A-Star-is-born''\n",
      "\u001b[1;31m\n",
      "\u001b[1;31mDuring handling of the above exception, another exception occurred:\n",
      "\u001b[1;31m\n",
      "\u001b[1;31mTraceback (most recent call last):\n",
      "\u001b[1;31m  File \"/Users/keanlee/.vscode/extensions/ms-toolsai.jupyter-2022.11.1003412109/pythonFiles/vscode_datascience_helpers/daemon/daemon_python.py\", line 54, in _decorator\n",
      "\u001b[1;31m    return func(self, *args, **kwargs)\n",
      "\u001b[1;31m  File \"/Users/keanlee/.vscode/extensions/ms-toolsai.jupyter-2022.11.1003412109/pythonFiles/vscode_datascience_helpers/jupyter_daemon.py\", line 111, in m_exec_module_observable\n",
      "\u001b[1;31m    self._start_notebook(args, cwd, env)\n",
      "\u001b[1;31m  File \"/Users/keanlee/.vscode/extensions/ms-toolsai.jupyter-2022.11.1003412109/pythonFiles/vscode_datascience_helpers/jupyter_daemon.py\", line 168, in _start_notebook\n",
      "\u001b[1;31m    app.launch_new_instance()\n",
      "\u001b[1;31m  File \"/Users/keanlee/opt/anaconda3/lib/python3.9/site-packages/jupyter_core/application.py\", line 269, in launch_instance\n",
      "\u001b[1;31m    return super().launch_instance(argv=argv, **kwargs)\n",
      "\u001b[1;31m  File \"/Users/keanlee/opt/anaconda3/lib/python3.9/site-packages/traitlets/config/application.py\", line 845, in launch_instance\n",
      "\u001b[1;31m    app.initialize(argv)\n",
      "\u001b[1;31m  File \"/Users/keanlee/opt/anaconda3/lib/python3.9/site-packages/traitlets/config/application.py\", line 88, in inner\n",
      "\u001b[1;31m    return method(app, *args, **kwargs)\n",
      "\u001b[1;31m  File \"/Users/keanlee/opt/anaconda3/lib/python3.9/site-packages/notebook/notebookapp.py\", line 2141, in initialize\n",
      "\u001b[1;31m    super().initialize(argv)\n",
      "\u001b[1;31m  File \"/Users/keanlee/opt/anaconda3/lib/python3.9/site-packages/traitlets/config/application.py\", line 88, in inner\n",
      "\u001b[1;31m    return method(app, *args, **kwargs)\n",
      "\u001b[1;31m  File \"/Users/keanlee/opt/anaconda3/lib/python3.9/site-packages/jupyter_core/application.py\", line 240, in initialize\n",
      "\u001b[1;31m    self.parse_command_line(argv)\n",
      "\u001b[1;31m  File \"/Users/keanlee/opt/anaconda3/lib/python3.9/site-packages/notebook/notebookapp.py\", line 1611, in parse_command_line\n",
      "\u001b[1;31m    super().parse_command_line(argv)\n",
      "\u001b[1;31m  File \"/Users/keanlee/opt/anaconda3/lib/python3.9/site-packages/traitlets/config/application.py\", line 92, in inner\n",
      "\u001b[1;31m    app.exit(1)\n",
      "\u001b[1;31m  File \"/Users/keanlee/opt/anaconda3/lib/python3.9/site-packages/traitlets/config/application.py\", line 836, in exit\n",
      "\u001b[1;31m    sys.exit(exit_status)\n",
      "\u001b[1;31mSystemExit: 1\n",
      "\u001b[1;31m\n",
      "\u001b[1;31m[C 09:33:01.858 NotebookApp] Bad config encountered during initialization: No such notebook dir: ''/kimolijones/A-Star-is-born''\n",
      "\u001b[1;31m\n",
      "\u001b[1;31mFailed to run jupyter as observable with args notebook --no-browser --notebook-dir=\"/kimolijones/A-Star-is-born\" --config=/var/folders/rh/bzc43zld6xg68hhsyrfwyx5m0000gn/T/6b58eeda-2a8e-41da-b6c2-119f77e59d55/jupyter_notebook_config.py --NotebookApp.iopub_data_rate_limit=10000000000.0"
     ]
    }
   ],
   "source": [
    "import ase.io # for reading *.xyz\n",
    "import pandas as pd # for dataframes?\n",
    "import matplotlib.pyplot as plt # for plotting error distribution"
   ]
  },
  {
   "cell_type": "markdown",
   "metadata": {},
   "source": [
    "# Setting Variables and Functions"
   ]
  },
  {
   "cell_type": "code",
   "execution_count": null,
   "metadata": {},
   "outputs": [
    {
     "ename": "",
     "evalue": "",
     "output_type": "error",
     "traceback": [
      "\u001b[1;31mFailed to start the Kernel. \n",
      "\u001b[1;31mTraceback (most recent call last):\n",
      "\u001b[1;31m  File \"/Users/keanlee/opt/anaconda3/lib/python3.9/site-packages/traitlets/config/application.py\", line 88, in inner\n",
      "\u001b[1;31m    return method(app, *args, **kwargs)\n",
      "\u001b[1;31m  File \"/Users/keanlee/opt/anaconda3/lib/python3.9/site-packages/traitlets/config/application.py\", line 714, in parse_command_line\n",
      "\u001b[1;31m    self.update_config(self.cli_config)\n",
      "\u001b[1;31m  File \"/Users/keanlee/opt/anaconda3/lib/python3.9/site-packages/traitlets/config/configurable.py\", line 223, in update_config\n",
      "\u001b[1;31m    self._load_config(config)\n",
      "\u001b[1;31m  File \"/Users/keanlee/opt/anaconda3/lib/python3.9/site-packages/traitlets/config/configurable.py\", line 193, in _load_config\n",
      "\u001b[1;31m    warn(msg)\n",
      "\u001b[1;31m  File \"/Users/keanlee/opt/anaconda3/lib/python3.9/contextlib.py\", line 126, in __exit__\n",
      "\u001b[1;31m    next(self.gen)\n",
      "\u001b[1;31m  File \"/Users/keanlee/opt/anaconda3/lib/python3.9/site-packages/traitlets/traitlets.py\", line 1207, in hold_trait_notifications\n",
      "\u001b[1;31m    raise e\n",
      "\u001b[1;31m  File \"/Users/keanlee/opt/anaconda3/lib/python3.9/site-packages/traitlets/traitlets.py\", line 1193, in hold_trait_notifications\n",
      "\u001b[1;31m    value = trait._cross_validate(self, getattr(self, name))\n",
      "\u001b[1;31m  File \"/Users/keanlee/opt/anaconda3/lib/python3.9/site-packages/traitlets/traitlets.py\", line 620, in _cross_validate\n",
      "\u001b[1;31m    value = obj._trait_validators<a href='obj, proposal'>self.name</a>\n",
      "\u001b[1;31m  File \"/Users/keanlee/opt/anaconda3/lib/python3.9/site-packages/traitlets/traitlets.py\", line 977, in __call__\n",
      "\u001b[1;31m    return self.func(*args, **kwargs)\n",
      "\u001b[1;31m  File \"/Users/keanlee/opt/anaconda3/lib/python3.9/site-packages/notebook/notebookapp.py\", line 1522, in _notebook_dir_validate\n",
      "\u001b[1;31m    raise TraitError(trans.gettext(\"No such notebook dir: '%r'\") % value)\n",
      "\u001b[1;31mtraitlets.traitlets.TraitError: No such notebook dir: ''/kimolijones/A-Star-is-born''\n",
      "\u001b[1;31m\n",
      "\u001b[1;31mDuring handling of the above exception, another exception occurred:\n",
      "\u001b[1;31m\n",
      "\u001b[1;31mTraceback (most recent call last):\n",
      "\u001b[1;31m  File \"/Users/keanlee/.vscode/extensions/ms-toolsai.jupyter-2022.11.1003412109/pythonFiles/vscode_datascience_helpers/daemon/daemon_python.py\", line 54, in _decorator\n",
      "\u001b[1;31m    return func(self, *args, **kwargs)\n",
      "\u001b[1;31m  File \"/Users/keanlee/.vscode/extensions/ms-toolsai.jupyter-2022.11.1003412109/pythonFiles/vscode_datascience_helpers/jupyter_daemon.py\", line 111, in m_exec_module_observable\n",
      "\u001b[1;31m    self._start_notebook(args, cwd, env)\n",
      "\u001b[1;31m  File \"/Users/keanlee/.vscode/extensions/ms-toolsai.jupyter-2022.11.1003412109/pythonFiles/vscode_datascience_helpers/jupyter_daemon.py\", line 168, in _start_notebook\n",
      "\u001b[1;31m    app.launch_new_instance()\n",
      "\u001b[1;31m  File \"/Users/keanlee/opt/anaconda3/lib/python3.9/site-packages/jupyter_core/application.py\", line 269, in launch_instance\n",
      "\u001b[1;31m    return super().launch_instance(argv=argv, **kwargs)\n",
      "\u001b[1;31m  File \"/Users/keanlee/opt/anaconda3/lib/python3.9/site-packages/traitlets/config/application.py\", line 845, in launch_instance\n",
      "\u001b[1;31m    app.initialize(argv)\n",
      "\u001b[1;31m  File \"/Users/keanlee/opt/anaconda3/lib/python3.9/site-packages/traitlets/config/application.py\", line 88, in inner\n",
      "\u001b[1;31m    return method(app, *args, **kwargs)\n",
      "\u001b[1;31m  File \"/Users/keanlee/opt/anaconda3/lib/python3.9/site-packages/notebook/notebookapp.py\", line 2141, in initialize\n",
      "\u001b[1;31m    super().initialize(argv)\n",
      "\u001b[1;31m  File \"/Users/keanlee/opt/anaconda3/lib/python3.9/site-packages/traitlets/config/application.py\", line 88, in inner\n",
      "\u001b[1;31m    return method(app, *args, **kwargs)\n",
      "\u001b[1;31m  File \"/Users/keanlee/opt/anaconda3/lib/python3.9/site-packages/jupyter_core/application.py\", line 240, in initialize\n",
      "\u001b[1;31m    self.parse_command_line(argv)\n",
      "\u001b[1;31m  File \"/Users/keanlee/opt/anaconda3/lib/python3.9/site-packages/notebook/notebookapp.py\", line 1611, in parse_command_line\n",
      "\u001b[1;31m    super().parse_command_line(argv)\n",
      "\u001b[1;31m  File \"/Users/keanlee/opt/anaconda3/lib/python3.9/site-packages/traitlets/config/application.py\", line 92, in inner\n",
      "\u001b[1;31m    app.exit(1)\n",
      "\u001b[1;31m  File \"/Users/keanlee/opt/anaconda3/lib/python3.9/site-packages/traitlets/config/application.py\", line 836, in exit\n",
      "\u001b[1;31m    sys.exit(exit_status)\n",
      "\u001b[1;31mSystemExit: 1\n",
      "\u001b[1;31m\n",
      "\u001b[1;31m[C 09:33:01.858 NotebookApp] Bad config encountered during initialization: No such notebook dir: ''/kimolijones/A-Star-is-born''\n",
      "\u001b[1;31m\n",
      "\u001b[1;31mFailed to run jupyter as observable with args notebook --no-browser --notebook-dir=\"/kimolijones/A-Star-is-born\" --config=/var/folders/rh/bzc43zld6xg68hhsyrfwyx5m0000gn/T/6b58eeda-2a8e-41da-b6c2-119f77e59d55/jupyter_notebook_config.py --NotebookApp.iopub_data_rate_limit=10000000000.0"
     ]
    }
   ],
   "source": [
    "DATASET_LOCATION = \"./data_structures_errors_head_5.xyz\""
   ]
  },
  {
   "cell_type": "code",
   "execution_count": null,
   "metadata": {},
   "outputs": [
    {
     "ename": "",
     "evalue": "",
     "output_type": "error",
     "traceback": [
      "\u001b[1;31mFailed to start the Kernel. \n",
      "\u001b[1;31mTraceback (most recent call last):\n",
      "\u001b[1;31m  File \"/Users/keanlee/opt/anaconda3/lib/python3.9/site-packages/traitlets/config/application.py\", line 88, in inner\n",
      "\u001b[1;31m    return method(app, *args, **kwargs)\n",
      "\u001b[1;31m  File \"/Users/keanlee/opt/anaconda3/lib/python3.9/site-packages/traitlets/config/application.py\", line 714, in parse_command_line\n",
      "\u001b[1;31m    self.update_config(self.cli_config)\n",
      "\u001b[1;31m  File \"/Users/keanlee/opt/anaconda3/lib/python3.9/site-packages/traitlets/config/configurable.py\", line 223, in update_config\n",
      "\u001b[1;31m    self._load_config(config)\n",
      "\u001b[1;31m  File \"/Users/keanlee/opt/anaconda3/lib/python3.9/site-packages/traitlets/config/configurable.py\", line 193, in _load_config\n",
      "\u001b[1;31m    warn(msg)\n",
      "\u001b[1;31m  File \"/Users/keanlee/opt/anaconda3/lib/python3.9/contextlib.py\", line 126, in __exit__\n",
      "\u001b[1;31m    next(self.gen)\n",
      "\u001b[1;31m  File \"/Users/keanlee/opt/anaconda3/lib/python3.9/site-packages/traitlets/traitlets.py\", line 1207, in hold_trait_notifications\n",
      "\u001b[1;31m    raise e\n",
      "\u001b[1;31m  File \"/Users/keanlee/opt/anaconda3/lib/python3.9/site-packages/traitlets/traitlets.py\", line 1193, in hold_trait_notifications\n",
      "\u001b[1;31m    value = trait._cross_validate(self, getattr(self, name))\n",
      "\u001b[1;31m  File \"/Users/keanlee/opt/anaconda3/lib/python3.9/site-packages/traitlets/traitlets.py\", line 620, in _cross_validate\n",
      "\u001b[1;31m    value = obj._trait_validators<a href='obj, proposal'>self.name</a>\n",
      "\u001b[1;31m  File \"/Users/keanlee/opt/anaconda3/lib/python3.9/site-packages/traitlets/traitlets.py\", line 977, in __call__\n",
      "\u001b[1;31m    return self.func(*args, **kwargs)\n",
      "\u001b[1;31m  File \"/Users/keanlee/opt/anaconda3/lib/python3.9/site-packages/notebook/notebookapp.py\", line 1522, in _notebook_dir_validate\n",
      "\u001b[1;31m    raise TraitError(trans.gettext(\"No such notebook dir: '%r'\") % value)\n",
      "\u001b[1;31mtraitlets.traitlets.TraitError: No such notebook dir: ''/kimolijones/A-Star-is-born''\n",
      "\u001b[1;31m\n",
      "\u001b[1;31mDuring handling of the above exception, another exception occurred:\n",
      "\u001b[1;31m\n",
      "\u001b[1;31mTraceback (most recent call last):\n",
      "\u001b[1;31m  File \"/Users/keanlee/.vscode/extensions/ms-toolsai.jupyter-2022.11.1003412109/pythonFiles/vscode_datascience_helpers/daemon/daemon_python.py\", line 54, in _decorator\n",
      "\u001b[1;31m    return func(self, *args, **kwargs)\n",
      "\u001b[1;31m  File \"/Users/keanlee/.vscode/extensions/ms-toolsai.jupyter-2022.11.1003412109/pythonFiles/vscode_datascience_helpers/jupyter_daemon.py\", line 111, in m_exec_module_observable\n",
      "\u001b[1;31m    self._start_notebook(args, cwd, env)\n",
      "\u001b[1;31m  File \"/Users/keanlee/.vscode/extensions/ms-toolsai.jupyter-2022.11.1003412109/pythonFiles/vscode_datascience_helpers/jupyter_daemon.py\", line 168, in _start_notebook\n",
      "\u001b[1;31m    app.launch_new_instance()\n",
      "\u001b[1;31m  File \"/Users/keanlee/opt/anaconda3/lib/python3.9/site-packages/jupyter_core/application.py\", line 269, in launch_instance\n",
      "\u001b[1;31m    return super().launch_instance(argv=argv, **kwargs)\n",
      "\u001b[1;31m  File \"/Users/keanlee/opt/anaconda3/lib/python3.9/site-packages/traitlets/config/application.py\", line 845, in launch_instance\n",
      "\u001b[1;31m    app.initialize(argv)\n",
      "\u001b[1;31m  File \"/Users/keanlee/opt/anaconda3/lib/python3.9/site-packages/traitlets/config/application.py\", line 88, in inner\n",
      "\u001b[1;31m    return method(app, *args, **kwargs)\n",
      "\u001b[1;31m  File \"/Users/keanlee/opt/anaconda3/lib/python3.9/site-packages/notebook/notebookapp.py\", line 2141, in initialize\n",
      "\u001b[1;31m    super().initialize(argv)\n",
      "\u001b[1;31m  File \"/Users/keanlee/opt/anaconda3/lib/python3.9/site-packages/traitlets/config/application.py\", line 88, in inner\n",
      "\u001b[1;31m    return method(app, *args, **kwargs)\n",
      "\u001b[1;31m  File \"/Users/keanlee/opt/anaconda3/lib/python3.9/site-packages/jupyter_core/application.py\", line 240, in initialize\n",
      "\u001b[1;31m    self.parse_command_line(argv)\n",
      "\u001b[1;31m  File \"/Users/keanlee/opt/anaconda3/lib/python3.9/site-packages/notebook/notebookapp.py\", line 1611, in parse_command_line\n",
      "\u001b[1;31m    super().parse_command_line(argv)\n",
      "\u001b[1;31m  File \"/Users/keanlee/opt/anaconda3/lib/python3.9/site-packages/traitlets/config/application.py\", line 92, in inner\n",
      "\u001b[1;31m    app.exit(1)\n",
      "\u001b[1;31m  File \"/Users/keanlee/opt/anaconda3/lib/python3.9/site-packages/traitlets/config/application.py\", line 836, in exit\n",
      "\u001b[1;31m    sys.exit(exit_status)\n",
      "\u001b[1;31mSystemExit: 1\n",
      "\u001b[1;31m\n",
      "\u001b[1;31m[C 09:33:01.858 NotebookApp] Bad config encountered during initialization: No such notebook dir: ''/kimolijones/A-Star-is-born''\n",
      "\u001b[1;31m\n",
      "\u001b[1;31mFailed to run jupyter as observable with args notebook --no-browser --notebook-dir=\"/kimolijones/A-Star-is-born\" --config=/var/folders/rh/bzc43zld6xg68hhsyrfwyx5m0000gn/T/6b58eeda-2a8e-41da-b6c2-119f77e59d55/jupyter_notebook_config.py --NotebookApp.iopub_data_rate_limit=10000000000.0"
     ]
    }
   ],
   "source": [
    "def sort_df(df, sort_method): # to sort df by certain column and display the line plot\n",
    "    df_sorted = df.sort_values(by=[sort_method])\n",
    "\n",
    "    plt.figure(figsize=(10,5))\n",
    "    plt.xlabel(sort_method.capitalize())\n",
    "    plt.ylabel(\"Energy (Error)\")\n",
    "    plt.ylim(-1.1*df[\"energy (error)\"].abs().max(), 1.1*df[\"energy (error)\"].abs().max())\n",
    "    plt.plot(df_sorted[sort_method], df_sorted['energy (error)'])\n",
    "    plt.scatter(df_sorted[sort_method], df_sorted['energy (error)'])\n",
    "    plt.axhline(y=0, color='r', linestyle='--')\n",
    "\n",
    "    plt.show()"
   ]
  },
  {
   "cell_type": "markdown",
   "metadata": {},
   "source": [
    "# Reading and Importing Dataset"
   ]
  },
  {
   "cell_type": "code",
   "execution_count": null,
   "metadata": {},
   "outputs": [
    {
     "ename": "",
     "evalue": "",
     "output_type": "error",
     "traceback": [
      "\u001b[1;31mFailed to start the Kernel. \n",
      "\u001b[1;31mTraceback (most recent call last):\n",
      "\u001b[1;31m  File \"/Users/keanlee/opt/anaconda3/lib/python3.9/site-packages/traitlets/config/application.py\", line 88, in inner\n",
      "\u001b[1;31m    return method(app, *args, **kwargs)\n",
      "\u001b[1;31m  File \"/Users/keanlee/opt/anaconda3/lib/python3.9/site-packages/traitlets/config/application.py\", line 714, in parse_command_line\n",
      "\u001b[1;31m    self.update_config(self.cli_config)\n",
      "\u001b[1;31m  File \"/Users/keanlee/opt/anaconda3/lib/python3.9/site-packages/traitlets/config/configurable.py\", line 223, in update_config\n",
      "\u001b[1;31m    self._load_config(config)\n",
      "\u001b[1;31m  File \"/Users/keanlee/opt/anaconda3/lib/python3.9/site-packages/traitlets/config/configurable.py\", line 193, in _load_config\n",
      "\u001b[1;31m    warn(msg)\n",
      "\u001b[1;31m  File \"/Users/keanlee/opt/anaconda3/lib/python3.9/contextlib.py\", line 126, in __exit__\n",
      "\u001b[1;31m    next(self.gen)\n",
      "\u001b[1;31m  File \"/Users/keanlee/opt/anaconda3/lib/python3.9/site-packages/traitlets/traitlets.py\", line 1207, in hold_trait_notifications\n",
      "\u001b[1;31m    raise e\n",
      "\u001b[1;31m  File \"/Users/keanlee/opt/anaconda3/lib/python3.9/site-packages/traitlets/traitlets.py\", line 1193, in hold_trait_notifications\n",
      "\u001b[1;31m    value = trait._cross_validate(self, getattr(self, name))\n",
      "\u001b[1;31m  File \"/Users/keanlee/opt/anaconda3/lib/python3.9/site-packages/traitlets/traitlets.py\", line 620, in _cross_validate\n",
      "\u001b[1;31m    value = obj._trait_validators<a href='obj, proposal'>self.name</a>\n",
      "\u001b[1;31m  File \"/Users/keanlee/opt/anaconda3/lib/python3.9/site-packages/traitlets/traitlets.py\", line 977, in __call__\n",
      "\u001b[1;31m    return self.func(*args, **kwargs)\n",
      "\u001b[1;31m  File \"/Users/keanlee/opt/anaconda3/lib/python3.9/site-packages/notebook/notebookapp.py\", line 1522, in _notebook_dir_validate\n",
      "\u001b[1;31m    raise TraitError(trans.gettext(\"No such notebook dir: '%r'\") % value)\n",
      "\u001b[1;31mtraitlets.traitlets.TraitError: No such notebook dir: ''/kimolijones/A-Star-is-born''\n",
      "\u001b[1;31m\n",
      "\u001b[1;31mDuring handling of the above exception, another exception occurred:\n",
      "\u001b[1;31m\n",
      "\u001b[1;31mTraceback (most recent call last):\n",
      "\u001b[1;31m  File \"/Users/keanlee/.vscode/extensions/ms-toolsai.jupyter-2022.11.1003412109/pythonFiles/vscode_datascience_helpers/daemon/daemon_python.py\", line 54, in _decorator\n",
      "\u001b[1;31m    return func(self, *args, **kwargs)\n",
      "\u001b[1;31m  File \"/Users/keanlee/.vscode/extensions/ms-toolsai.jupyter-2022.11.1003412109/pythonFiles/vscode_datascience_helpers/jupyter_daemon.py\", line 111, in m_exec_module_observable\n",
      "\u001b[1;31m    self._start_notebook(args, cwd, env)\n",
      "\u001b[1;31m  File \"/Users/keanlee/.vscode/extensions/ms-toolsai.jupyter-2022.11.1003412109/pythonFiles/vscode_datascience_helpers/jupyter_daemon.py\", line 168, in _start_notebook\n",
      "\u001b[1;31m    app.launch_new_instance()\n",
      "\u001b[1;31m  File \"/Users/keanlee/opt/anaconda3/lib/python3.9/site-packages/jupyter_core/application.py\", line 269, in launch_instance\n",
      "\u001b[1;31m    return super().launch_instance(argv=argv, **kwargs)\n",
      "\u001b[1;31m  File \"/Users/keanlee/opt/anaconda3/lib/python3.9/site-packages/traitlets/config/application.py\", line 845, in launch_instance\n",
      "\u001b[1;31m    app.initialize(argv)\n",
      "\u001b[1;31m  File \"/Users/keanlee/opt/anaconda3/lib/python3.9/site-packages/traitlets/config/application.py\", line 88, in inner\n",
      "\u001b[1;31m    return method(app, *args, **kwargs)\n",
      "\u001b[1;31m  File \"/Users/keanlee/opt/anaconda3/lib/python3.9/site-packages/notebook/notebookapp.py\", line 2141, in initialize\n",
      "\u001b[1;31m    super().initialize(argv)\n",
      "\u001b[1;31m  File \"/Users/keanlee/opt/anaconda3/lib/python3.9/site-packages/traitlets/config/application.py\", line 88, in inner\n",
      "\u001b[1;31m    return method(app, *args, **kwargs)\n",
      "\u001b[1;31m  File \"/Users/keanlee/opt/anaconda3/lib/python3.9/site-packages/jupyter_core/application.py\", line 240, in initialize\n",
      "\u001b[1;31m    self.parse_command_line(argv)\n",
      "\u001b[1;31m  File \"/Users/keanlee/opt/anaconda3/lib/python3.9/site-packages/notebook/notebookapp.py\", line 1611, in parse_command_line\n",
      "\u001b[1;31m    super().parse_command_line(argv)\n",
      "\u001b[1;31m  File \"/Users/keanlee/opt/anaconda3/lib/python3.9/site-packages/traitlets/config/application.py\", line 92, in inner\n",
      "\u001b[1;31m    app.exit(1)\n",
      "\u001b[1;31m  File \"/Users/keanlee/opt/anaconda3/lib/python3.9/site-packages/traitlets/config/application.py\", line 836, in exit\n",
      "\u001b[1;31m    sys.exit(exit_status)\n",
      "\u001b[1;31mSystemExit: 1\n",
      "\u001b[1;31m\n",
      "\u001b[1;31m[C 09:33:01.858 NotebookApp] Bad config encountered during initialization: No such notebook dir: ''/kimolijones/A-Star-is-born''\n",
      "\u001b[1;31m\n",
      "\u001b[1;31mFailed to run jupyter as observable with args notebook --no-browser --notebook-dir=\"/kimolijones/A-Star-is-born\" --config=/var/folders/rh/bzc43zld6xg68hhsyrfwyx5m0000gn/T/6b58eeda-2a8e-41da-b6c2-119f77e59d55/jupyter_notebook_config.py --NotebookApp.iopub_data_rate_limit=10000000000.0"
     ]
    }
   ],
   "source": [
    "dataset_list = list(ase.io.iread(filename=DATASET_LOCATION, format=\"extxyz\")) # reading *.xyz file as a generator, then converting into list\n",
    "df = pd.DataFrame(dataset_list)\n",
    "\n",
    "df[\"number of atoms\"] = [dataset_list[i].get_global_number_of_atoms() for i in range(len(dataset_list))]\n",
    "df[\"chemical formula\"] = [dataset_list[i].get_chemical_formula() for i in range(len(dataset_list))]\n",
    "df[\"Lattice (unit cell with three vectors)\"] = [dataset_list[i].get_cell()[:] for i in range(len(dataset_list))]\n",
    "df[\"volume of unit cell (derived from Lattice)\"] = [dataset_list[i].get_cell().volume for i in range(len(dataset_list))]\n",
    "df[\"energy (error)\"] = [dataset_list[i].info[\"energy\"] for i in range(len(dataset_list))]\n",
    "# Properties part not impt; pbc is \"T T T\" for all\n",
    "\n",
    "display(df.head())\n",
    "\n",
    "# possible way of extracting data out from Atom object\n",
    "# print(df[0][0])\n",
    "# print(df[0][0].symbol)\n",
    "# print(df[0][0].position)"
   ]
  },
  {
   "cell_type": "markdown",
   "metadata": {},
   "source": [
    "# Exploratory Analysis"
   ]
  },
  {
   "cell_type": "code",
   "execution_count": null,
   "metadata": {},
   "outputs": [
    {
     "ename": "",
     "evalue": "",
     "output_type": "error",
     "traceback": [
      "\u001b[1;31mFailed to start the Kernel. \n",
      "\u001b[1;31mTraceback (most recent call last):\n",
      "\u001b[1;31m  File \"/Users/keanlee/opt/anaconda3/lib/python3.9/site-packages/traitlets/config/application.py\", line 88, in inner\n",
      "\u001b[1;31m    return method(app, *args, **kwargs)\n",
      "\u001b[1;31m  File \"/Users/keanlee/opt/anaconda3/lib/python3.9/site-packages/traitlets/config/application.py\", line 714, in parse_command_line\n",
      "\u001b[1;31m    self.update_config(self.cli_config)\n",
      "\u001b[1;31m  File \"/Users/keanlee/opt/anaconda3/lib/python3.9/site-packages/traitlets/config/configurable.py\", line 223, in update_config\n",
      "\u001b[1;31m    self._load_config(config)\n",
      "\u001b[1;31m  File \"/Users/keanlee/opt/anaconda3/lib/python3.9/site-packages/traitlets/config/configurable.py\", line 193, in _load_config\n",
      "\u001b[1;31m    warn(msg)\n",
      "\u001b[1;31m  File \"/Users/keanlee/opt/anaconda3/lib/python3.9/contextlib.py\", line 126, in __exit__\n",
      "\u001b[1;31m    next(self.gen)\n",
      "\u001b[1;31m  File \"/Users/keanlee/opt/anaconda3/lib/python3.9/site-packages/traitlets/traitlets.py\", line 1207, in hold_trait_notifications\n",
      "\u001b[1;31m    raise e\n",
      "\u001b[1;31m  File \"/Users/keanlee/opt/anaconda3/lib/python3.9/site-packages/traitlets/traitlets.py\", line 1193, in hold_trait_notifications\n",
      "\u001b[1;31m    value = trait._cross_validate(self, getattr(self, name))\n",
      "\u001b[1;31m  File \"/Users/keanlee/opt/anaconda3/lib/python3.9/site-packages/traitlets/traitlets.py\", line 620, in _cross_validate\n",
      "\u001b[1;31m    value = obj._trait_validators<a href='obj, proposal'>self.name</a>\n",
      "\u001b[1;31m  File \"/Users/keanlee/opt/anaconda3/lib/python3.9/site-packages/traitlets/traitlets.py\", line 977, in __call__\n",
      "\u001b[1;31m    return self.func(*args, **kwargs)\n",
      "\u001b[1;31m  File \"/Users/keanlee/opt/anaconda3/lib/python3.9/site-packages/notebook/notebookapp.py\", line 1522, in _notebook_dir_validate\n",
      "\u001b[1;31m    raise TraitError(trans.gettext(\"No such notebook dir: '%r'\") % value)\n",
      "\u001b[1;31mtraitlets.traitlets.TraitError: No such notebook dir: ''/kimolijones/A-Star-is-born''\n",
      "\u001b[1;31m\n",
      "\u001b[1;31mDuring handling of the above exception, another exception occurred:\n",
      "\u001b[1;31m\n",
      "\u001b[1;31mTraceback (most recent call last):\n",
      "\u001b[1;31m  File \"/Users/keanlee/.vscode/extensions/ms-toolsai.jupyter-2022.11.1003412109/pythonFiles/vscode_datascience_helpers/daemon/daemon_python.py\", line 54, in _decorator\n",
      "\u001b[1;31m    return func(self, *args, **kwargs)\n",
      "\u001b[1;31m  File \"/Users/keanlee/.vscode/extensions/ms-toolsai.jupyter-2022.11.1003412109/pythonFiles/vscode_datascience_helpers/jupyter_daemon.py\", line 111, in m_exec_module_observable\n",
      "\u001b[1;31m    self._start_notebook(args, cwd, env)\n",
      "\u001b[1;31m  File \"/Users/keanlee/.vscode/extensions/ms-toolsai.jupyter-2022.11.1003412109/pythonFiles/vscode_datascience_helpers/jupyter_daemon.py\", line 168, in _start_notebook\n",
      "\u001b[1;31m    app.launch_new_instance()\n",
      "\u001b[1;31m  File \"/Users/keanlee/opt/anaconda3/lib/python3.9/site-packages/jupyter_core/application.py\", line 269, in launch_instance\n",
      "\u001b[1;31m    return super().launch_instance(argv=argv, **kwargs)\n",
      "\u001b[1;31m  File \"/Users/keanlee/opt/anaconda3/lib/python3.9/site-packages/traitlets/config/application.py\", line 845, in launch_instance\n",
      "\u001b[1;31m    app.initialize(argv)\n",
      "\u001b[1;31m  File \"/Users/keanlee/opt/anaconda3/lib/python3.9/site-packages/traitlets/config/application.py\", line 88, in inner\n",
      "\u001b[1;31m    return method(app, *args, **kwargs)\n",
      "\u001b[1;31m  File \"/Users/keanlee/opt/anaconda3/lib/python3.9/site-packages/notebook/notebookapp.py\", line 2141, in initialize\n",
      "\u001b[1;31m    super().initialize(argv)\n",
      "\u001b[1;31m  File \"/Users/keanlee/opt/anaconda3/lib/python3.9/site-packages/traitlets/config/application.py\", line 88, in inner\n",
      "\u001b[1;31m    return method(app, *args, **kwargs)\n",
      "\u001b[1;31m  File \"/Users/keanlee/opt/anaconda3/lib/python3.9/site-packages/jupyter_core/application.py\", line 240, in initialize\n",
      "\u001b[1;31m    self.parse_command_line(argv)\n",
      "\u001b[1;31m  File \"/Users/keanlee/opt/anaconda3/lib/python3.9/site-packages/notebook/notebookapp.py\", line 1611, in parse_command_line\n",
      "\u001b[1;31m    super().parse_command_line(argv)\n",
      "\u001b[1;31m  File \"/Users/keanlee/opt/anaconda3/lib/python3.9/site-packages/traitlets/config/application.py\", line 92, in inner\n",
      "\u001b[1;31m    app.exit(1)\n",
      "\u001b[1;31m  File \"/Users/keanlee/opt/anaconda3/lib/python3.9/site-packages/traitlets/config/application.py\", line 836, in exit\n",
      "\u001b[1;31m    sys.exit(exit_status)\n",
      "\u001b[1;31mSystemExit: 1\n",
      "\u001b[1;31m\n",
      "\u001b[1;31m[C 09:33:01.858 NotebookApp] Bad config encountered during initialization: No such notebook dir: ''/kimolijones/A-Star-is-born''\n",
      "\u001b[1;31m\n",
      "\u001b[1;31mFailed to run jupyter as observable with args notebook --no-browser --notebook-dir=\"/kimolijones/A-Star-is-born\" --config=/var/folders/rh/bzc43zld6xg68hhsyrfwyx5m0000gn/T/6b58eeda-2a8e-41da-b6c2-119f77e59d55/jupyter_notebook_config.py --NotebookApp.iopub_data_rate_limit=10000000000.0"
     ]
    }
   ],
   "source": [
    "display(df.describe())\n",
    "sort_df(df, \"number of atoms\")\n",
    "sort_df(df, \"volume of unit cell (derived from Lattice)\")\n"
   ]
  },
  {
   "cell_type": "code",
   "execution_count": null,
   "metadata": {},
   "outputs": [
    {
     "ename": "",
     "evalue": "",
     "output_type": "error",
     "traceback": [
      "\u001b[1;31mFailed to start the Kernel. \n",
      "\u001b[1;31mTraceback (most recent call last):\n",
      "\u001b[1;31m  File \"/Users/keanlee/opt/anaconda3/lib/python3.9/site-packages/traitlets/config/application.py\", line 88, in inner\n",
      "\u001b[1;31m    return method(app, *args, **kwargs)\n",
      "\u001b[1;31m  File \"/Users/keanlee/opt/anaconda3/lib/python3.9/site-packages/traitlets/config/application.py\", line 714, in parse_command_line\n",
      "\u001b[1;31m    self.update_config(self.cli_config)\n",
      "\u001b[1;31m  File \"/Users/keanlee/opt/anaconda3/lib/python3.9/site-packages/traitlets/config/configurable.py\", line 223, in update_config\n",
      "\u001b[1;31m    self._load_config(config)\n",
      "\u001b[1;31m  File \"/Users/keanlee/opt/anaconda3/lib/python3.9/site-packages/traitlets/config/configurable.py\", line 193, in _load_config\n",
      "\u001b[1;31m    warn(msg)\n",
      "\u001b[1;31m  File \"/Users/keanlee/opt/anaconda3/lib/python3.9/contextlib.py\", line 126, in __exit__\n",
      "\u001b[1;31m    next(self.gen)\n",
      "\u001b[1;31m  File \"/Users/keanlee/opt/anaconda3/lib/python3.9/site-packages/traitlets/traitlets.py\", line 1207, in hold_trait_notifications\n",
      "\u001b[1;31m    raise e\n",
      "\u001b[1;31m  File \"/Users/keanlee/opt/anaconda3/lib/python3.9/site-packages/traitlets/traitlets.py\", line 1193, in hold_trait_notifications\n",
      "\u001b[1;31m    value = trait._cross_validate(self, getattr(self, name))\n",
      "\u001b[1;31m  File \"/Users/keanlee/opt/anaconda3/lib/python3.9/site-packages/traitlets/traitlets.py\", line 620, in _cross_validate\n",
      "\u001b[1;31m    value = obj._trait_validators<a href='obj, proposal'>self.name</a>\n",
      "\u001b[1;31m  File \"/Users/keanlee/opt/anaconda3/lib/python3.9/site-packages/traitlets/traitlets.py\", line 977, in __call__\n",
      "\u001b[1;31m    return self.func(*args, **kwargs)\n",
      "\u001b[1;31m  File \"/Users/keanlee/opt/anaconda3/lib/python3.9/site-packages/notebook/notebookapp.py\", line 1522, in _notebook_dir_validate\n",
      "\u001b[1;31m    raise TraitError(trans.gettext(\"No such notebook dir: '%r'\") % value)\n",
      "\u001b[1;31mtraitlets.traitlets.TraitError: No such notebook dir: ''/kimolijones/A-Star-is-born''\n",
      "\u001b[1;31m\n",
      "\u001b[1;31mDuring handling of the above exception, another exception occurred:\n",
      "\u001b[1;31m\n",
      "\u001b[1;31mTraceback (most recent call last):\n",
      "\u001b[1;31m  File \"/Users/keanlee/.vscode/extensions/ms-toolsai.jupyter-2022.11.1003412109/pythonFiles/vscode_datascience_helpers/daemon/daemon_python.py\", line 54, in _decorator\n",
      "\u001b[1;31m    return func(self, *args, **kwargs)\n",
      "\u001b[1;31m  File \"/Users/keanlee/.vscode/extensions/ms-toolsai.jupyter-2022.11.1003412109/pythonFiles/vscode_datascience_helpers/jupyter_daemon.py\", line 111, in m_exec_module_observable\n",
      "\u001b[1;31m    self._start_notebook(args, cwd, env)\n",
      "\u001b[1;31m  File \"/Users/keanlee/.vscode/extensions/ms-toolsai.jupyter-2022.11.1003412109/pythonFiles/vscode_datascience_helpers/jupyter_daemon.py\", line 168, in _start_notebook\n",
      "\u001b[1;31m    app.launch_new_instance()\n",
      "\u001b[1;31m  File \"/Users/keanlee/opt/anaconda3/lib/python3.9/site-packages/jupyter_core/application.py\", line 269, in launch_instance\n",
      "\u001b[1;31m    return super().launch_instance(argv=argv, **kwargs)\n",
      "\u001b[1;31m  File \"/Users/keanlee/opt/anaconda3/lib/python3.9/site-packages/traitlets/config/application.py\", line 845, in launch_instance\n",
      "\u001b[1;31m    app.initialize(argv)\n",
      "\u001b[1;31m  File \"/Users/keanlee/opt/anaconda3/lib/python3.9/site-packages/traitlets/config/application.py\", line 88, in inner\n",
      "\u001b[1;31m    return method(app, *args, **kwargs)\n",
      "\u001b[1;31m  File \"/Users/keanlee/opt/anaconda3/lib/python3.9/site-packages/notebook/notebookapp.py\", line 2141, in initialize\n",
      "\u001b[1;31m    super().initialize(argv)\n",
      "\u001b[1;31m  File \"/Users/keanlee/opt/anaconda3/lib/python3.9/site-packages/traitlets/config/application.py\", line 88, in inner\n",
      "\u001b[1;31m    return method(app, *args, **kwargs)\n",
      "\u001b[1;31m  File \"/Users/keanlee/opt/anaconda3/lib/python3.9/site-packages/jupyter_core/application.py\", line 240, in initialize\n",
      "\u001b[1;31m    self.parse_command_line(argv)\n",
      "\u001b[1;31m  File \"/Users/keanlee/opt/anaconda3/lib/python3.9/site-packages/notebook/notebookapp.py\", line 1611, in parse_command_line\n",
      "\u001b[1;31m    super().parse_command_line(argv)\n",
      "\u001b[1;31m  File \"/Users/keanlee/opt/anaconda3/lib/python3.9/site-packages/traitlets/config/application.py\", line 92, in inner\n",
      "\u001b[1;31m    app.exit(1)\n",
      "\u001b[1;31m  File \"/Users/keanlee/opt/anaconda3/lib/python3.9/site-packages/traitlets/config/application.py\", line 836, in exit\n",
      "\u001b[1;31m    sys.exit(exit_status)\n",
      "\u001b[1;31mSystemExit: 1\n",
      "\u001b[1;31m\n",
      "\u001b[1;31m[C 09:33:01.858 NotebookApp] Bad config encountered during initialization: No such notebook dir: ''/kimolijones/A-Star-is-born''\n",
      "\u001b[1;31m\n",
      "\u001b[1;31mFailed to run jupyter as observable with args notebook --no-browser --notebook-dir=\"/kimolijones/A-Star-is-born\" --config=/var/folders/rh/bzc43zld6xg68hhsyrfwyx5m0000gn/T/6b58eeda-2a8e-41da-b6c2-119f77e59d55/jupyter_notebook_config.py --NotebookApp.iopub_data_rate_limit=10000000000.0"
     ]
    }
   ],
   "source": []
  }
 ],
 "metadata": {
  "kernelspec": {
   "display_name": "base",
   "language": "python",
   "name": "python3"
  },
  "language_info": {
   "codemirror_mode": {
    "name": "ipython",
    "version": 3
   },
   "file_extension": ".py",
   "mimetype": "text/x-python",
   "name": "python",
   "nbconvert_exporter": "python",
   "pygments_lexer": "ipython3",
   "version": "3.9.13 (main, Aug 25 2022, 18:29:29) \n[Clang 12.0.0 ]"
  },
  "orig_nbformat": 4,
  "vscode": {
   "interpreter": {
    "hash": "c5f5005e4baef62d22f0c6a54b00ced40c50a3d03d4c16a187624b06789a3ad5"
   }
  }
 },
 "nbformat": 4,
 "nbformat_minor": 2
}
